import React from 'react';
import { render, screen, fireEvent } from '@testing-library/react';
import { ErrorBoundary } from '../ErrorBoundary';

// Component that throws an error for testing
const ThrowError: React.FC<{ shouldThrow?: boolean }> = ({
  shouldThrow = false,
}) => {
  if (shouldThrow) {
    throw new Error('Test error');
  }
  return <div>No error</div>;
};

// Mock console.error to avoid noise in test output
const originalError = console.error;
beforeAll(() => {
  console.error = jest.fn();
});

afterAll(() => {
  console.error = originalError;
});

describe('ErrorBoundary', () => {
  it('should render children when there is no error', () => {
    render(
      <ErrorBoundary>
        <ThrowError shouldThrow={false} />
      </ErrorBoundary>
    );

    expect(screen.getByText('No error')).toBeInTheDocument();
  });

  it('should render error UI when there is an error', () => {
    render(
      <ErrorBoundary>
        <ThrowError shouldThrow={true} />
      </ErrorBoundary>
    );

    expect(screen.getByText('Oops! Something went wrong')).toBeInTheDocument();
    expect(
      screen.getByText(/We're sorry, but something unexpected happened/)
    ).toBeInTheDocument();
    expect(screen.getByText('Error: Test error')).toBeInTheDocument();
  });

  it('should show Try Again and Reload Page buttons', () => {
    render(
      <ErrorBoundary>
        <ThrowError shouldThrow={true} />
      </ErrorBoundary>
    );

    expect(screen.getByText('Try Again')).toBeInTheDocument();
    expect(screen.getByText('Reload Page')).toBeInTheDocument();
  });

  it('should reset error state when Try Again is clicked', () => {
    const { rerender } = render(
      <ErrorBoundary>
        <ThrowError shouldThrow={true} />
      </ErrorBoundary>
    );

    expect(screen.getByText('Oops! Something went wrong')).toBeInTheDocument();

    fireEvent.click(screen.getByText('Try Again'));

    // Re-render with no error
    rerender(
      <ErrorBoundary>
        <ThrowError shouldThrow={false} />
      </ErrorBoundary>
    );

    expect(screen.getByText('No error')).toBeInTheDocument();
  });

  it('should render custom fallback when provided', () => {
    const customFallback = <div>Custom error message</div>;

    render(
      <ErrorBoundary fallback={customFallback}>
        <ThrowError shouldThrow={true} />
      </ErrorBoundary>
    );

    expect(screen.getByText('Custom error message')).toBeInTheDocument();
    expect(
      screen.queryByText('Oops! Something went wrong')
    ).not.toBeInTheDocument();
  });

  it('should show error details in development mode', () => {
    const originalEnv = process.env.NODE_ENV;
    process.env.NODE_ENV = 'development';

    render(
      <ErrorBoundary>
        <ThrowError shouldThrow={true} />
      </ErrorBoundary>
    );

    expect(
      screen.getByText('Error Details (Development Only):')
    ).toBeInTheDocument();

    process.env.NODE_ENV = originalEnv;
  });

  it('should hide error details in production mode', () => {
    const originalEnv = process.env.NODE_ENV;
    process.env.NODE_ENV = 'production';

    render(
      <ErrorBoundary>
        <ThrowError shouldThrow={true} />
      </ErrorBoundary>
    );

    expect(
      screen.queryByText('Error Details (Development Only):')
    ).not.toBeInTheDocument();

    process.env.NODE_ENV = originalEnv;
  });

  it('should log error to console', () => {
    const consoleSpy = jest
      .spyOn(console, 'error')
      .mockImplementation(() => {});

    render(
      <ErrorBoundary>
        <ThrowError shouldThrow={true} />
      </ErrorBoundary>
    );

    expect(consoleSpy).toHaveBeenCalledWith(
      'ErrorBoundary caught an error:',
      expect.any(Error),
      expect.any(Object)
    );

    consoleSpy.mockRestore();
  });
});
